Workbook

Sheet Sheet2
A1: Type | B1: Task
A3: Row Labels | B3: Sum of Estimated Hours
A4: Hardik | B4: 110
A5: Ronak | B5: 111
A6: Soumy Oza | B6: 100
A7: Parth Jani | B7: 79
A8: Grand Total | B8: 400

Sheet WBS
A1: WBS ID | B1: Task Name | C1: Type | D1: Estimated Hours | E1: Developer
A2: 1 | B2: HIMAPP 2.0 — Admin Module Implementation | C2: Project | D2: =D3+D24+D58+D75+D93+D115+D133+D153+D175+D193+D196 -> 400
A3: 1.1 | B3: Epic 1: Dashboard & KPIs | C3: Epic | D3: =D4+D9+D14+D19 -> 48
A4: 1.1.1 | B4: US-01: Admin Views Real-Time Project Dashboard | C4: User Story | D4: =SUM(D5:D8) -> 12 | E4: Developer
A5: 1.1.1.1 | B5: Database | C5: Task | D5: 2 | E5: Parth Jani
A6: 1.1.1.2 | B6: Backend API | C6: Task | D6: 3 | E6: Parth Jani
A7: 1.1.1.3 | B7: Web Front End | C7: Task | D7: 3 | E7: Parth Jani
A8: 1.1.1.4 | B8: Mobile | C8: Task | D8: 4 | E8: Hardik
A9: 1.1.2 | B9: US-02: Ready-to-Issue Banner Highlights Cleared Workers | C9: User Story | D9: =SUM(D10:D13) -> 12 | E9: Developer
A10: 1.1.1.1 | B10: Database | C10: Task | D10: 2 | E10: Parth Jani
A11: 1.1.2.1 | B11: Backend API | C11: Task | D11: 3 | E11: Parth Jani
A12: 1.1.2.2 | B12: Web Front End | C12: Task | D12: 3 | E12: Parth Jani
A13: 1.1.2.3 | B13: Mobile | C13: Task | D13: 4 | E13: Hardik
A14: 1.1.3 | B14: US-03: Recently Registered Labour List with Quick Actions | C14: User Story | D14: =SUM(D15:D18) -> 12 | E14: Developer
A15: 1.1.1.1 | B15: Database | C15: Task | D15: 2 | E15: Parth Jani
A16: 1.1.3.1 | B16: Backend API | C16: Task | D16: 3 | E16: Parth Jani
A17: 1.1.3.2 | B17: Web Front End | C17: Task | D17: 3 | E17: Parth Jani
A18: 1.1.3.3 | B18: Mobile | C18: Task | D18: 4 | E18: Hardik
A19: 1.1.4 | B19: US-04: Expiring Gatepasses Widget with Renew Shortcut | C19: User Story | D19: =SUM(D20:D23) -> 12 | E19: Developer
A20: 1.1.1.1 | B20: Database | C20: Task | D20: 2 | E20: Parth Jani
A21: 1.1.4.1 | B21: Backend API | C21: Task | D21: 3 | E21: Parth Jani
A22: 1.1.4.2 | B22: Web Front End | C22: Task | D22: 3 | E22: Parth Jani
A23: 1.1.4.3 | B23: Mobile | C23: Task | D23: 4 | E23: Hardik
A24: 1.2 | B24: Epic 2: Labour Registration | C24: Epic | D24: =D25+D30+D34+D38+D42+D46+D50+D54 -> 53
A25: 1.2.1 | B25: US-05: Admin Registers New Labour via Four-Section Form | C25: User Story | D25: =SUM(D26:D29) -> 14 | E25: Developer
A26: 1.2.1.1 | B26: Database | C26: Task | D26: 2 | E26: Parth Jani
A27: 1.2.1.2 | B27: Backend API | C27: Task | D27: 4 | E27: Ronak
A28: 1.2.1.3 | B28: Web Front End | C28: Task | D28: 4 | E28: Soumy Oza
A29: 1.2.1.4 | B29: Mobile | C29: Task | D29: 4 | E29: Hardik
A30: 1.2.2 | B30: US-06: Auto-Fill Contractor Contact Number on Selection | C30: User Story | D30: =SUM(D31:D33) -> 4 | E30: Developer
A31: 1.2.2.1 | B31: Backend API | C31: Task | D31: 2 | E31: Ronak
A32: 1.2.2.2 | B32: Web Front End | C32: Task | D32: 1 | E32: Soumy Oza
A33: 1.2.2.3 | B33: Mobile | C33: Task | D33: 1 | E33: Hardik
A34: 1.2.3 | B34: US-07: System Validates Minimum Age of 18 Years at Registration | C34: User Story | D34: =SUM(D35:D37) -> 4 | E34: Developer
A35: 1.2.3.1 | B35: Backend API | C35: Task | D35: 2 | E35: Ronak
A36: 1.2.3.2 | B36: Web Front End | C36: Task | D36: 1 | E36: Soumy Oza
A37: 1.2.3.3 | B37: Mobile | C37: Task | D37: 1 | E37: Hardik
A38: 1.2.4 | B38: US-08: System Enforces Aadhaar Mandatory Format and Masking | C38: User Story | D38: =SUM(D39:D41) -> 4 | E38: Developer
A39: 1.2.4.1 | B39: Backend API | C39: Task | D39: 2 | E39: Ronak
A40: 1.2.4.2 | B40: Web Front End | C40: Task | D40: 1 | E40: Soumy Oza
...

Sheet Epic Timeline
A1: HIMAPP 2.0 ADMIN MODULE — EPIC-LEVEL TIMELINE
A2: WBS ID | B2: Epic | C2: Estimated Hours | D2: Days
A3: 1.1 | B3: Epic 1: Dashboard & KPIs | C3: =WBS!D3 -> 48 | D3: =C3/6 -> 8 | H3: Row Labels | I3: Estimated Hours | J3: Days
A4: 1.2 | B4: Epic 2: Labour Registration | C4: =WBS!D24 -> 53 | D4: =C4/6 -> 8.8333333 | H4: Hardik | I4: 110 | J4: =+I4/6 -> 18.333333
A5: 1.3 | B5: Epic 3: Multi-Project Reuse & Duplicate Prevention | C5: =WBS!D58 -> 22 | D5: =C5/6 -> 3.6666667 | H5: Ronak | I5: 111 | J5: =+I5/6 -> 18.5
A6: 1.4 | B6: Epic 4: Labour List, Search & Export | C6: =WBS!D75 -> 26 | D6: =C6/6 -> 4.3333333 | H6: Soumy Oza | I6: 100 | J6: =+I6/6 -> 16.666667
A7: 1.5 | B7: Epic 5: Gatepass Issuance | C7: =WBS!D93 -> 54 | D7: =C7/6 -> 9 | H7: Parth Jani | I7: 79 | J7: =+I7/6 -> 13.166667
A8: 1.6 | B8: Epic 6: Gatepass Renewal & Revocation | C8: =WBS!D115 -> 33 | D8: =C8/6 -> 5.5 | H8: Grand Total | I8: 400 | J8: =MAX(J4:J7) -> 18.5
A9: 1.7 | B9: Epic 7: Bulk Print & Printable Gatepass Slip | C9: =WBS!D133 -> 37 | D9: =C9/6 -> 6.1666667
A10: 1.8 | B10: Epic 8: Colony Assignment | C10: =WBS!D153 -> 64 | D10: =C10/6 -> 10.666667
A11: 1.9 | B11: Epic 9: Notifications & Alerts | C11: =WBS!D175 -> 24 | D11: =C11/6 -> 4
A12: 1.10 | B12: Epic 10: Mobile Experience | C12: =WBS!D193 -> 6 | D12: =C12/6 -> 1
A13: 1.11 | B13: Epic 11: Integrations, Reporting & NFRs | C13: =WBS!D196 -> 33 | D13: =C13/6 -> 5.5
B14: PROJECT TOTAL | C14: =SUM(C3:C13) -> 400 | D14: =C14/6 -> 66.666667
