Workbook
Name BufferDays: Settings!$B$5
Name Holidays: Holidays!$A$2:$A$60
Name HoursPerDay: Settings!$B$4
Name StartDate: Settings!$B$3

Sheet Settings
A1: All Module Estimations — Schedule Settings
A3: Project Start Date | B3: 46219
A4: Working Hours / Day | B4: 7
A5: Buffer Between Modules (working days) | B5: 7
A8: Module Order
A9: # | B9: Module | C9: Module Start Date | D9: Day Zero (helper)
A10: 1 | B10: Execution | C10: =$B$3 -> 46219 | D10: =WORKDAY($C10,-1,Holidays) -> 46218
A11: 2 | B11: Admin | C11: =WORKDAY('All Modules WBS'!$J$2,$B$5+1,Holidays) -> 46260 | D11: =WORKDAY($C11,-1,Holidays) -> 46259
A12: 3 | B12: Safety | C12: =WORKDAY('All Modules WBS'!$J$223,$B$5+1,Holidays) -> 46293 | D12: =WORKDAY($C12,-1,Holidays) -> 46290
A13: 4 | B13: P&M | C13: =WORKDAY('All Modules WBS'!$J$433,$B$5+1,Holidays) -> 46336 | D13: =WORKDAY($C13,-1,Holidays) -> 46335
A14: 5 | B14: Store | C14: =WORKDAY('All Modules WBS'!$J$620,$B$5+1,Holidays) -> 46401 | D14: =WORKDAY($C14,-1,Holidays) -> 46400
A18: HOW THIS FILE WORKS:
A19: 1. Working hours per day = 7 (editable above). The schedule is calculated in WORKING HOURS, so several small tasks
A20: can be completed on the same day. "Start Hr"/"End Hr" = cumulative working hours of that developer within the module.
A21: 2. All developers work IN PARALLEL: each developer completes his own tasks one after another (top to bottom),
A22: so a module finishes when its busiest developer finishes.
A23: 3. Modules run sequentially: Execution -> Admin -> Safety -> P&M -> Store, with a 3-working-day buffer between modules.
A24: 4. Saturdays, Sundays and all dates on the "Holidays" sheet are excluded automatically.
A25: 5. Everything is live formulas — change Start Date, Hours/Day, Buffer, any Estimated Hours, or any Start Hr,
A26: and every downstream task, Epic, Module and Developer date updates automatically (cascades across modules too).
A27: 6. 0-hour tasks are milestones (consume no time). Epic / User Story / Project rows roll up from their children.

Sheet Holidays
A1: Holiday Date | B1: Holiday Name
A2: 46249 | B2: Independence Day (Saturday) | D2: Add / edit company holidays in column A (rows 2-60); they are excluded from the schedule automatically.
A3: 46297 | B3: Gandhi Jayanti
A4: 46381 | B4: Christmas Day
A5: 46413 | B5: Republic Day

Sheet All Modules WBS
A1: Module | B1: WBS ID | C1: Task Name | D1: Type | E1: Estimated Hours | F1: Developer | G1: Start Hr | H1: End Hr | I1: Start Date | J1: End Date
A2: Execution | B2: 1 | C2: HIMAPP 2.0 — SITE EXECUTION MODULE — Implementation | D2: Project | E2: =SUMIF($D3:$D222,"Task",$E3:$E222) -> 564 | I2: =MIN($I3:$I222) -> 46219 | J2: =MAX($J3:$J222) -> 46248
A3: Execution | B3: 1.1 | C3: Epic 1: Manpower & Labour Deployment (AM Entry) | D3: Epic | E3: =SUMIF($D4:$D18,"Task",$E4:$E18) -> 40 | I3: =MIN($I4:$I18) -> 46219 | J3: =MAX($J4:$J18) -> 46223
A4: Execution | B4: 1.1.1 | C4: US-01: Field Engineer Logs Morning Manpower Deployment | D4: User Story | E4: =SUMIF($D5:$D8,"Task",$E5:$E8) -> 20 | I4: =MIN($I5:$I8) -> 46219 | J4: =MAX($J5:$J8) -> 46220
A5: Execution | B5: 1.1.1.1 | C5: Database | D5: Task | E5: 3 | F5: Ronak | G5: =0 -> 0 | H5: =$G5+$E5 -> 3 | I5: =WORKDAY(Settings!$D$10,INT($G5/HoursPerDay)+1,Holidays) -> 46219 | J5: =IF($E5=0,$I5,WORKDAY(Settings!$D$10,ROUNDUP($H5/HoursPerDay,0),Holidays)) -> 46219
A6: Execution | B6: 1.1.1.2 | C6: Backend API | D6: Task | E6: 6 | F6: Ronak | G6: =$H$5 -> 3 | H6: =$G6+$E6 -> 9 | I6: =WORKDAY(Settings!$D$10,INT($G6/HoursPerDay)+1,Holidays) -> 46219 | J6: =IF($E6=0,$I6,WORKDAY(Settings!$D$10,ROUNDUP($H6/HoursPerDay,0),Holidays)) -> 46220
A7: Execution | B7: 1.1.1.3 | C7: Web Front End | D7: Task | E7: 5 | F7: Soumy | G7: =0 -> 0 | H7: =$G7+$E7 -> 5 | I7: =WORKDAY(Settings!$D$10,INT($G7/HoursPerDay)+1,Holidays) -> 46219 | J7: =IF($E7=0,$I7,WORKDAY(Settings!$D$10,ROUNDUP($H7/HoursPerDay,0),Holidays)) -> 46219
A8: Execution | B8: 1.1.1.4 | C8: Mobile | D8: Task | E8: 6 | F8: Hardik | G8: =0 -> 0 | H8: =$G8+$E8 -> 6 | I8: =WORKDAY(Settings!$D$10,INT($G8/HoursPerDay)+1,Holidays) -> 46219 | J8: =IF($E8=0,$I8,WORKDAY(Settings!$D$10,ROUNDUP($H8/HoursPerDay,0),Holidays)) -> 46219
A9: Execution | B9: 1.1.2 | C9: US-02: System Carries Saved Manpower Forward into Daily DPR | D9: User Story | E9: =SUMIF($D10:$D13,"Task",$E10:$E13) -> 10 | I9: =MIN($I10:$I13) -> 46219 | J9: =MAX($J10:$J13) -> 46220
A10: Execution | B10: 1.1.2.1 | C10: Database | D10: Task | E10: 2 | F10: Ronak | G10: =$H$6 -> 9 | H10: =$G10+$E10 -> 11 | I10: =WORKDAY(Settings!$D$10,INT($G10/HoursPerDay)+1,Holidays) -> 46220 | J10: =IF($E10=0,$I10,WORKDAY(Settings!$D$10,ROUNDUP($H10/HoursPerDay,0),Holidays)) -> 46220
A11: Execution | B11: 1.1.2.2 | C11: Backend API | D11: Task | E11: 3 | F11: Ronak | G11: =$H$10 -> 11 | H11: =$G11+$E11 -> 14 | I11: =WORKDAY(Settings!$D$10,INT($G11/HoursPerDay)+1,Holidays) -> 46220 | J11: =IF($E11=0,$I11,WORKDAY(Settings!$D$10,ROUNDUP($H11/HoursPerDay,0),Holidays)) -> 46220
A12: Execution | B12: 1.1.2.3 | C12: Web Front End | D12: Task | E12: 3 | F12: Soumy | G12: =$H$7 -> 5 | H12: =$G12+$E12 -> 8 | I12: =WORKDAY(Settings!$D$10,INT($G12/HoursPerDay)+1,Holidays) -> 46219 | J12: =IF($E12=0,$I12,WORKDAY(Settings!$D$10,ROUNDUP($H12/HoursPerDay,0),Holidays)) -> 46220
A13: Execution | B13: 1.1.2.4 | C13: Mobile | D13: Task | E13: 2 | F13: Hardik | G13: =$H$8 -> 6 | H13: =$G13+$E13 -> 8 | I13: =WORKDAY(Settings!$D$10,INT($G13/HoursPerDay)+1,Holidays) -> 46219 | J13: =IF($E13=0,$I13,WORKDAY(Settings!$D$10,ROUNDUP($H13/HoursPerDay,0),Holidays)) -> 46220
A14: Execution | B14: 1.1.3 | C14: US-03: Add, Tag, and Remove Contractors with Work Category | D14: User Story | E14: =SUMIF($D15:$D18,"Task",$E15:$E18) -> 10 | I14: =MIN($I15:$I18) -> 46220 | J14: =MAX($J15:$J18) -> 46223
A15: Execution | B15: 1.1.3.1 | C15: Database | D15: Task | E15: 2 | F15: Ronak | G15: =$H$11 -> 14 | H15: =$G15+$E15 -> 16 | I15: =WORKDAY(Settings!$D$10,INT($G15/HoursPerDay)+1,Holidays) -> 46223 | J15: =IF($E15=0,$I15,WORKDAY(Settings!$D$10,ROUNDUP($H15/HoursPerDay,0),Holidays)) -> 46223
A16: Execution | B16: 1.1.3.2 | C16: Backend API | D16: Task | E16: 3 | F16: Ronak | G16: =$H$15 -> 16 | H16: =$G16+$E16 -> 19 | I16: =WORKDAY(Settings!$D$10,INT($G16/HoursPerDay)+1,Holidays) -> 46223 | J16: =IF($E16=0,$I16,WORKDAY(Settings!$D$10,ROUNDUP($H16/HoursPerDay,0),Holidays)) -> 46223
A17: Execution | B17: 1.1.3.3 | C17: Web Front End | D17: Task | E17: 3 | F17: Soumy | G17: =$H$12 -> 8 | H17: =$G17+$E17 -> 11 | I17: =WORKDAY(Settings!$D$10,INT($G17/HoursPerDay)+1,Holidays) -> 46220 | J17: =IF($E17=0,$I17,WORKDAY(Settings!$D$10,ROUNDUP($H17/HoursPerDay,0),Holidays)) -> 46220
A18: Execution | B18: 1.1.3.4 | C18: Mobile | D18: Task | E18: 2 | F18: Hardik | G18: =$H$13 -> 8 | H18: =$G18+$E18 -> 10 | I18: =WORKDAY(Settings!$D$10,INT($G18/HoursPerDay)+1,Holidays) -> 46220 | J18: =IF($E18=0,$I18,WORKDAY(Settings!$D$10,ROUNDUP($H18/HoursPerDay,0),Holidays)) -> 46220
A19: Execution | B19: 1.2 | C19: Epic 2: Site DPR & Project DPR Consolidation | D19: Epic | E19: =SUMIF($D20:$D70,"Task",$E20:$E70) -> 124 | I19: =MIN($I20:$I70) -> 46219 | J19: =MAX($J20:$J70) -> 46230
A20: Execution | B20: 1.2.1 | C20: US-04: Engineer Records Per-Section Activity Quantities Against Plan | D20: User Story | E20: =SUMIF($D21:$D24,"Task",$E21:$E24) -> 14 | I20: =MIN($I21:$I24) -> 46219 | J20: =MAX($J21:$J24) -> 46223
A21: Execution | B21: 1.2.1.1 | C21: Database | D21: Task | E21: 2 | F21: Parth Jani | G21: =0 -> 0 | H21: =$G21+$E21 -> 2 | I21: =WORKDAY(Settings!$D$10,INT($G21/HoursPerDay)+1,Holidays) -> 46219 | J21: =IF($E21=0,$I21,WORKDAY(Settings!$D$10,ROUNDUP($H21/HoursPerDay,0),Holidays)) -> 46219
A22: Execution | B22: 1.2.1.2 | C22: Backend API | D22: Task | E22: 3 | F22: Parth Jani | G22: =$H$21 -> 2 | H22: =$G22+$E22 -> 5 | I22: =WORKDAY(Settings!$D$10,INT($G22/HoursPerDay)+1,Holidays) -> 46219 | J22: =IF($E22=0,$I22,WORKDAY(Settings!$D$10,ROUNDUP($H22/HoursPerDay,0),Holidays)) -> 46219
A23: Execution | B23: 1.2.1.3 | C23: Web Front End | D23: Task | E23: 4 | F23: Soumy | G23: =$H$17 -> 11 | H23: =$G23+$E23 -> 15 | I23: =WORKDAY(Settings!$D$10,INT($G23/HoursPerDay)+1,Holidays) -> 46220 | J23: =IF($E23=0,$I23,WORKDAY(Settings!$D$10,ROUNDUP($H23/HoursPerDay,0),Holidays)) -> 46223
A24: Execution | B24: 1.2.1.4 | C24: Mobile | D24: Task | E24: 5 | F24: Hardik | G24: =$H$18 -> 10 | H24: =$G24+$E24 -> 15 | I24: =WORKDAY(Settings!$D$10,INT($G24/HoursPerDay)+1,Holidays) -> 46220 | J24: =IF($E24=0,$I24,WORKDAY(Settings!$D$10,ROUNDUP($H24/HoursPerDay,0),Holidays)) -> 46223
A25: Execution | B25: 1.2.2 | C25: US-05: QS Enters Quantities via Cross-Section Quantity Matrix | D25: User Story | E25: =SUMIF($D26:$D29,"Task",$E26:$E29) -> 13 | I25: =MIN($I26:$I29) -> 46219 | J25: =MAX($J26:$J29) -> 46223
A26: Execution | B26: 1.2.2.1 | C26: Database | D26: Task | E26: 2 | F26: Parth Jani | G26: =$H$22 -> 5 | H26: =$G26+$E26 -> 7 | I26: =WORKDAY(Settings!$D$10,INT($G26/HoursPerDay)+1,Holidays) -> 46219 | J26: =IF($E26=0,$I26,WORKDAY(Settings!$D$10,ROUNDUP($H26/HoursPerDay,0),Holidays)) -> 46219
A27: Execution | B27: 1.2.2.2 | C27: Backend API | D27: Task | E27: 4 | F27: Parth Jani | G27: =$H$26 -> 7 | H27: =$G27+$E27 -> 11 | I27: =WORKDAY(Settings!$D$10,INT($G27/HoursPerDay)+1,Holidays) -> 46220 | J27: =IF($E27=0,$I27,WORKDAY(Settings!$D$10,ROUNDUP($H27/HoursPerDay,0),Holidays)) -> 46220
A28: Execution | B28: 1.2.2.3 | C28: Web Front End | D28: Task | E28: 4 | F28: Soumy | G28: =$H$23 -> 15 | H28: =$G28+$E28 -> 19 | I28: =WORKDAY(Settings!$D$10,INT($G28/HoursPerDay)+1,Holidays) -> 46223 | J28: =IF($E28=0,$I28,WORKDAY(Settings!$D$10,ROUNDUP($H28/HoursPerDay,0),Holidays)) -> 46223
A29: Execution | B29: 1.2.2.4 | C29: Mobile | D29: Task | E29: 3 | F29: Hardik | G29: =$H$24 -> 15 | H29: =$G29+$E29 -> 18 | I29: =WORKDAY(Settings!$D$10,INT($G29/HoursPerDay)+1,Holidays) -> 46223 | J29: =IF($E29=0,$I29,WORKDAY(Settings!$D$10,ROUNDUP($H29/HoursPerDay,0),Holidays)) -> 46223
A30: Execution | B30: 1.2.3 | C30: US-06: Bulk Quantity Entry via Excel Template Upload | D30: User Story | E30: =SUMIF($D31:$D33,"Task",$E31:$E33) -> 12 | I30: =MIN($I31:$I33) -> 46220 | J30: =MAX($J31:$J33) -> 46224
A31: Execution | B31: 1.2.3.1 | C31: Database | D31: Task | E31: 1 | F31: Parth Jani | G31: =$H$27 -> 11 | H31: =$G31+$E31 -> 12 | I31: =WORKDAY(Settings!$D$10,INT($G31/HoursPerDay)+1,Holidays) -> 46220 | J31: =IF($E31=0,$I31,WORKDAY(Settings!$D$10,ROUNDUP($H31/HoursPerDay,0),Holidays)) -> 46220
A32: Execution | B32: 1.2.3.2 | C32: Backend API | D32: Task | E32: 6 | F32: Parth Jani | G32: =$H$31 -> 12 | H32: =$G32+$E32 -> 18 | I32: =WORKDAY(Settings!$D$10,INT($G32/HoursPerDay)+1,Holidays) -> 46220 | J32: =IF($E32=0,$I32,WORKDAY(Settings!$D$10,ROUNDUP($H32/HoursPerDay,0),Holidays)) -> 46223
A33: Execution | B33: 1.2.3.3 | C33: Web Front End | D33: Task | E33: 5 | F33: Soumy | G33: =$H$28 -> 19 | H33: =$G33+$E33 -> 24 | I33: =WORKDAY(Settings!$D$10,INT($G33/HoursPerDay)+1,Holidays) -> 46223 | J33: =IF($E33=0,$I33,WORKDAY(Settings!$D$10,ROUNDUP($H33/HoursPerDay,0),Holidays)) -> 46224
A34: Execution | B34: 1.2.4 | C34: US-07: Capture Hindrances with Auto-Classification | D34: User Story | E34: =SUMIF($D35:$D38,"Task",$E35:$E38) -> 12 | I34: =MIN($I35:$I38) -> 46223 | J34: =MAX($J35:$J38) -> 46224
A35: Execution | B35: 1.2.4.1 | C35: Database | D35: Task | E35: 1 | F35: Parth Jani | G35: =$H$32 -> 18 | H35: =$G35+$E35 -> 19 | I35: =WORKDAY(Settings!$D$10,INT($G35/HoursPerDay)+1,Holidays) -> 46223 | J35: =IF($E35=0,$I35,WORKDAY(Settings!$D$10,ROUNDUP($H35/HoursPerDay,0),Holidays)) -> 46223
A36: Execution | B36: 1.2.4.2 | C36: Backend API | D36: Task | E36: 4 | F36: Parth Jani | G36: =$H$35 -> 19 | H36: =$G36+$E36 -> 23 | I36: =WORKDAY(Settings!$D$10,INT($G36/HoursPerDay)+1,Holidays) -> 46223 | J36: =IF($E36=0,$I36,WORKDAY(Settings!$D$10,ROUNDUP($H36/HoursPerDay,0),Holidays)) -> 46224
A37: Execution | B37: 1.2.4.3 | C37: Web Front End | D37: Task | E37: 4 | F37: Soumy | G37: =$H$33 -> 24 | H37: =$G37+$E37 -> 28 | I37: =WORKDAY(Settings!$D$10,INT($G37/HoursPerDay)+1,Holidays) -> 46224 | J37: =IF($E37=0,$I37,WORKDAY(Settings!$D$10,ROUNDUP($H37/HoursPerDay,0),Holidays)) -> 46224
A38: Execution | B38: 1.2.4.4 | C38: Mobile | D38: Task | E38: 3 | F38: Hardik | G38: =$H$29 -> 18 | H38: =$G38+$E38 -> 21 | I38: =WORKDAY(Settings!$D$10,INT($G38/HoursPerDay)+1,Holidays) -> 46223 | J38: =IF($E38=0,$I38,WORKDAY(Settings!$D$10,ROUNDUP($H38/HoursPerDay,0),Holidays)) -> 46223
A39: Execution | B39: 1.2.5 | C39: US-08: Capture GPS Tag and Site Photo for Daily Record | D39: User Story | E39: =SUMIF($D40:$D43,"Task",$E40:$E43) -> 12 | I39: =MIN($I40:$I43) -> 46224 | J39: =MAX($J40:$J43) -> 46225
A40: Execution | B40: 1.2.5.1 | C40: Database | D40: Task | E40: 1 | F40: Parth Jani | G40: =$H$36 -> 23 | H40: =$G40+$E40 -> 24 | I40: =WORKDAY(Settings!$D$10,INT($G40/HoursPerDay)+1,Holidays) -> 46224 | J40: =IF($E40=0,$I40,WORKDAY(Settings!$D$10,ROUNDUP($H40/HoursPerDay,0),Holidays)) -> 46224
...

Sheet Summary
A1: Module-wise Schedule (modules sequential, 3 working-day buffer between modules)
A2: Module | B2: Total Hours | C2: Working Days | D2: Start Date | E2: End Date
A3: Execution | B3: =SUMIFS('All Modules WBS'!$E:$E,'All Modules WBS'!$A:$A,$A3,'All Modules WBS'!$D:$D,"Task") -> 564 | C3: =NETWORKDAYS($D3,$E3,Holidays) -> 22 | D3: ='All Modules WBS'!$I$2 -> 46219 | E3: ='All Modules WBS'!$J$2 -> 46248
A4: Admin | B4: =SUMIFS('All Modules WBS'!$E:$E,'All Modules WBS'!$A:$A,$A4,'All Modules WBS'!$D:$D,"Task") -> 400 | C4: =NETWORKDAYS($D4,$E4,Holidays) -> 16 | D4: ='All Modules WBS'!$I$223 -> 46260 | E4: ='All Modules WBS'!$J$223 -> 46281
A5: Safety | B5: =SUMIFS('All Modules WBS'!$E:$E,'All Modules WBS'!$A:$A,$A5,'All Modules WBS'!$D:$D,"Task") -> 558 | C5: =NETWORKDAYS($D5,$E5,Holidays) -> 23 | D5: ='All Modules WBS'!$I$433 -> 46293 | E5: ='All Modules WBS'!$J$433 -> 46324
A6: P&M | B6: =SUMIFS('All Modules WBS'!$E:$E,'All Modules WBS'!$A:$A,$A6,'All Modules WBS'!$D:$D,"Task") -> 1045 | C6: =NETWORKDAYS($D6,$E6,Holidays) -> 39 | D6: ='All Modules WBS'!$I$620 -> 46336 | E6: ='All Modules WBS'!$J$620 -> 46391
A7: Store | B7: =SUMIFS('All Modules WBS'!$E:$E,'All Modules WBS'!$A:$A,$A7,'All Modules WBS'!$D:$D,"Task") -> 286 | C7: =NETWORKDAYS($D7,$E7,Holidays) -> 10 | D7: ='All Modules WBS'!$I$1010 -> 46401 | E7: ='All Modules WBS'!$J$1010 -> 46415
A8: TOTAL | B8: =SUM(B3:B7) -> 2853 | C8: =NETWORKDAYS(D8,E8,Holidays) -> 138 | D8: =MIN(D3:D7) -> 46219 | E8: =MAX(E3:E7) -> 46415
A10: Developer-wise Hours by Module (developers work in parallel)
A11: Developer | B11: Execution | C11: Admin | D11: Safety | E11: P&M | F11: Store | G11: Total Hours | H11: First Task Start | I11: Last Task End
A12: Parth Jani | B12: =SUMIFS('All Modules WBS'!$E:$E,'All Modules WBS'!$F:$F,$A12,'All Modules WBS'!$A:$A,B$11,'All Modules WBS'!$D:$D,"Task") -> 150 | C12: =SUMIFS('All Modules WBS'!$E:$E,'All Modules WBS'!$F:$F,$A12,'All Modules WBS'!$A:$A,C$11,'All Modules WBS'!$D:$D,"Task") -> 79 | D12: =SUMIFS('All Modules WBS'!$E:$E,'All Modules WBS'!$F:$F,$A12,'All Modules WBS'!$A:$A,D$11,'All Modules WBS'!$D:$D,"Task") -> 110 | E12: =SUMIFS('All Modules WBS'!$E:$E,'All Modules WBS'!$F:$F,$A12,'All Modules WBS'!$A:$A,E$11,'All Modules WBS'!$D:$D,"Task") -> 262 | F12: =SUMIFS('All Modules WBS'!$E:$E,'All Modules WBS'!$F:$F,$A12,'All Modules WBS'!$A:$A,F$11,'All Modules WBS'!$D:$D,"Task") -> 53 | G12: =SUM(B12:F12) -> 654 | H12: ='All Modules WBS'!$I$21 -> 46219 | I12: ='All Modules WBS'!$J$1235 -> 46412
A13: Ronak | B13: =SUMIFS('All Modules WBS'!$E:$E,'All Modules WBS'!$F:$F,$A13,'All Modules WBS'!$A:$A,B$11,'All Modules WBS'!$D:$D,"Task") -> 144 | C13: =SUMIFS('All Modules WBS'!$E:$E,'All Modules WBS'!$F:$F,$A13,'All Modules WBS'!$A:$A,C$11,'All Modules WBS'!$D:$D,"Task") -> 111 | D13: =SUMIFS('All Modules WBS'!$E:$E,'All Modules WBS'!$F:$F,$A13,'All Modules WBS'!$A:$A,D$11,'All Modules WBS'!$D:$D,"Task") -> 151 | E13: =SUMIFS('All Modules WBS'!$E:$E,'All Modules WBS'!$F:$F,$A13,'All Modules WBS'!$A:$A,E$11,'All Modules WBS'!$D:$D,"Task") -> 200 | F13: =SUMIFS('All Modules WBS'!$E:$E,'All Modules WBS'!$F:$F,$A13,'All Modules WBS'!$A:$A,F$11,'All Modules WBS'!$D:$D,"Task") -> 64 | G13: =SUM(B13:F13) -> 670 | H13: ='All Modules WBS'!$I$5 -> 46219 | I13: ='All Modules WBS'!$J$1118 -> 46415
A14: Soumy | B14: =SUMIFS('All Modules WBS'!$E:$E,'All Modules WBS'!$F:$F,$A14,'All Modules WBS'!$A:$A,B$11,'All Modules WBS'!$D:$D,"Task") -> 147 | C14: =SUMIFS('All Modules WBS'!$E:$E,'All Modules WBS'!$F:$F,$A14,'All Modules WBS'!$A:$A,C$11,'All Modules WBS'!$D:$D,"Task") -> 100 | D14: =SUMIFS('All Modules WBS'!$E:$E,'All Modules WBS'!$F:$F,$A14,'All Modules WBS'!$A:$A,D$11,'All Modules WBS'!$D:$D,"Task") -> 138 | E14: =SUMIFS('All Modules WBS'!$E:$E,'All Modules WBS'!$F:$F,$A14,'All Modules WBS'!$A:$A,E$11,'All Modules WBS'!$D:$D,"Task") -> 268 | F14: =SUMIFS('All Modules WBS'!$E:$E,'All Modules WBS'!$F:$F,$A14,'All Modules WBS'!$A:$A,F$11,'All Modules WBS'!$D:$D,"Task") -> 56 | G14: =SUM(B14:F14) -> 709 | H14: ='All Modules WBS'!$I$7 -> 46219 | I14: ='All Modules WBS'!$J$1124 -> 46412
A15: Hardik | B15: =SUMIFS('All Modules WBS'!$E:$E,'All Modules WBS'!$F:$F,$A15,'All Modules WBS'!$A:$A,B$11,'All Modules WBS'!$D:$D,"Task") -> 123 | C15: =SUMIFS('All Modules WBS'!$E:$E,'All Modules WBS'!$F:$F,$A15,'All Modules WBS'!$A:$A,C$11,'All Modules WBS'!$D:$D,"Task") -> 110 | D15: =SUMIFS('All Modules WBS'!$E:$E,'All Modules WBS'!$F:$F,$A15,'All Modules WBS'!$A:$A,D$11,'All Modules WBS'!$D:$D,"Task") -> 159 | E15: =SUMIFS('All Modules WBS'!$E:$E,'All Modules WBS'!$F:$F,$A15,'All Modules WBS'!$A:$A,E$11,'All Modules WBS'!$D:$D,"Task") -> 248 | F15: =SUMIFS('All Modules WBS'!$E:$E,'All Modules WBS'!$F:$F,$A15,'All Modules WBS'!$A:$A,F$11,'All Modules WBS'!$D:$D,"Task") -> 45 | G15: =SUM(B15:F15) -> 685 | H15: ='All Modules WBS'!$I$8 -> 46219 | I15: ='All Modules WBS'!$J$1237 -> 46409
A16: Inderjeet | B16: =SUMIFS('All Modules WBS'!$E:$E,'All Modules WBS'!$F:$F,$A16,'All Modules WBS'!$A:$A,B$11,'All Modules WBS'!$D:$D,"Task") -> 0 | C16: =SUMIFS('All Modules WBS'!$E:$E,'All Modules WBS'!$F:$F,$A16,'All Modules WBS'!$A:$A,C$11,'All Modules WBS'!$D:$D,"Task") -> 0 | D16: =SUMIFS('All Modules WBS'!$E:$E,'All Modules WBS'!$F:$F,$A16,'All Modules WBS'!$A:$A,D$11,'All Modules WBS'!$D:$D,"Task") -> 0 | E16: =SUMIFS('All Modules WBS'!$E:$E,'All Modules WBS'!$F:$F,$A16,'All Modules WBS'!$A:$A,E$11,'All Modules WBS'!$D:$D,"Task") -> 67 | F16: =SUMIFS('All Modules WBS'!$E:$E,'All Modules WBS'!$F:$F,$A16,'All Modules WBS'!$A:$A,F$11,'All Modules WBS'!$D:$D,"Task") -> 68 | G16: =SUM(B16:F16) -> 135 | H16: ='All Modules WBS'!$I$645 -> 46336 | I16: ='All Modules WBS'!$J$1236 -> 46415
A17: TOTAL | B17: =SUM(B12:B16) -> 564 | C17: =SUM(C12:C16) -> 400 | D17: =SUM(D12:D16) -> 558 | E17: =SUM(E12:E16) -> 1045 | F17: =SUM(F12:F16) -> 286 | G17: =SUM(G12:G16) -> 2853
