Workbook

Sheet Sheet1
A1: Type | B1: Task
A3: Row Labels | B3: Sum of Estimated Hours | C3: Estimation Days
A4: Hardik | B4: 248 | C4: =+GETPIVOTDATA("Estimated Hours",$A$3,"Developer","Hardik")/7 -> 35.428571
A5: Parth | B5: 262 | C5: =+GETPIVOTDATA("Estimated Hours",$A$3,"Developer","Parth")/7 -> 37.428571
A6: Ronak | B6: 200 | C6: =+GETPIVOTDATA("Estimated Hours",$A$3,"Developer","Ronak")/7 -> 28.571429
A7: Soumy | B7: 268 | C7: =+GETPIVOTDATA("Estimated Hours",$A$3,"Developer","Soumy")/7 -> 38.285714
A8: Inderjeet | B8: 67 | C8: =+GETPIVOTDATA("Estimated Hours",$A$3,"Developer","Inderjeet")/7 -> 9.5714286
A9: Grand Total | B9: 1045 | C9: =MAX(C4:C8) -> 38.285714

Sheet WBS
A1: WBS ID | B1: Task Name | C1: Type | D1: Estimated Hours | E1: Developer
A2: 1 | B2: HIMAPP 2.0 — PLANT & MACHINERY (PM) MODULE — Implementation | C2: Project | D2: =D3+D63+D88+D136+D215+D254+D284+D327 -> 1045
A3: 1.1 | B3: Epic 1: Equipment Management | C3: Epic | D3: =D4+D8+D11+D14+D17+D20+D24+D28+D32+D36+D40+D44+D47+D51+D55+D59 -> 176
A4: 1.1.1 | B4: PNM-001: Sync Equipment Master from D365 | C4: User Story | D4: =SUM(D5:D7) -> 15 | E4: Developer
A5: 1.1.1.1 | B5: Database | C5: Task | D5: 3 | E5: Parth
A6: 1.1.1.2 | B6: Backend API | C6: Task | D6: 6 | E6: Parth
A7: 1.1.1.3 | B7: Web Front End | C7: Task | D7: 6 | E7: Soumy
A8: 1.1.2 | B8: PNM-002: View Equipment List (Equipment 360) | C8: User Story | D8: =SUM(D9:D10) -> 12 | E8: Developer
A9: 1.1.2.1 | B9: Backend API | C9: Task | D9: 6 | E9: Parth
A10: 1.1.2.2 | B10: Web Front End | C10: Task | D10: 6 | E10: Soumy
A11: 1.1.3 | B11: PNM-003: Search Equipment | C11: User Story | D11: =SUM(D12:D13) -> 8 | E11: Developer
A12: 1.1.3.1 | B12: Backend API | C12: Task | D12: 4 | E12: Parth
A13: 1.1.3.2 | B13: Web Front End | C13: Task | D13: 4 | E13: Soumy
A14: 1.1.4 | B14: PNM-004: View Equipment Detail — Overview Tab | C14: User Story | D14: =SUM(D15:D16) -> 8 | E14: Developer
A15: 1.1.4.1 | B15: Backend API | C15: Task | D15: 4 | E15: Parth
A16: 1.1.4.2 | B16: Web Front End | C16: Task | D16: 4 | E16: Soumy
A17: 1.1.5 | B17: PNM-005: View Equipment Lifecycle History | C17: User Story | D17: =SUM(D18:D19) -> 8 | E17: Developer
A18: 1.1.5.1 | B18: Backend API | C18: Task | D18: 4 | E18: Parth
A19: 1.1.5.2 | B19: Web Front End | C19: Task | D19: 4 | E19: Soumy
A20: 1.1.6 | B20: PNM-006: Assign Equipment to Project (Initial Assignment) | C20: User Story | D20: =SUM(D21:D23) -> 10 | E20: Developer
A21: 1.1.6.1 | B21: Database | C21: Task | D21: 2 | E21: Parth
A22: 1.1.6.2 | B22: Backend API | C22: Task | D22: 4 | E22: Parth
A23: 1.1.6.3 | B23: Web Front End | C23: Task | D23: 4 | E23: Soumy
A24: 1.1.7 | B24: PNM-008: Raise Equipment Condition Report (ECR) — Sender | C24: User Story | D24: =SUM(D25:D27) -> 15 | E24: Developer
A25: 1.1.7.1 | B25: Database | C25: Task | D25: 3 | E25: Parth
A26: 1.1.7.2 | B26: Backend API | C26: Task | D26: 6 | E26: Parth
A27: 1.1.7.3 | B27: Web Front End | C27: Task | D27: 6 | E27: Inderjeet
A28: 1.1.8 | B28: PNM-009: Auto-Cancel Open Spare MRIS on Transfer Completion | C28: User Story | D28: =SUM(D29:D31) -> 10 | E28: Developer
A29: 1.1.8.1 | B29: Database | C29: Task | D29: 2 | E29: Parth
A30: 1.1.8.2 | B30: Backend API | C30: Task | D30: 4 | E30: Parth
A31: 1.1.8.3 | B31: Web Front End | C31: Task | D31: 4 | E31: Soumy
A32: 1.1.9 | B32: PNM-010: Acknowledge Incoming Equipment — Receiver ECR | C32: User Story | D32: =SUM(D33:D35) -> 15 | E32: Developer
A33: 1.1.9.1 | B33: Database | C33: Task | D33: 3 | E33: Parth
A34: 1.1.9.2 | B34: Backend API | C34: Task | D34: 6 | E34: Parth
A35: 1.1.9.3 | B35: Web Front End | C35: Task | D35: 6 | E35: Inderjeet
A36: 1.1.10 | B36: PNM-011: Auto-Complete Equipment Transfer | C36: User Story | D36: =SUM(D37:D39) -> 10 | E36: Developer
A37: 1.1.10.1 | B37: Database | C37: Task | D37: 2 | E37: Parth
A38: 1.1.10.2 | B38: Backend API | C38: Task | D38: 4 | E38: Parth
A39: 1.1.10.3 | B39: Web Front End | C39: Task | D39: 4 | E39: Soumy
A40: 1.1.11 | B40: PNM-012: Resolve ECR Dispute | C40: User Story | D40: =SUM(D41:D43) -> 10 | E40: Developer
...

Sheet Epic Timeline
A1: WBS ID | B1: Task Name | C1: Estimated Hours | D1: Days
A2: 1.1 | B2: Epic 1: Equipment Management | C2: =WBS!D3 -> 176 | D2: =C2/6 -> 29.333333 | F2: Row Labels | G2: Sum of Estimated Hours | H2: Estimation Days
A3: 1.2 | B3: Epic 2: Daily Equipment Checklist | C3: =WBS!D63 -> 76 | D3: =C3/6 -> 12.666667 | F3: Hardik | G3: 248 | H3: 35.428571
A4: 1.3 | B4: Epic 3: Digital Log Book | C4: =WBS!D88 -> 155 | D4: =C4/6 -> 25.833333 | F4: Parth | G4: 262 | H4: 37.428571
A5: 1.4 | B5: Epic 4: Breakdown Management | C5: =WBS!D136 -> 262 | D5: =C5/6 -> 43.666667 | F5: Ronak | G5: 200 | H5: 28.571429
A6: 1.5 | B6: Epic 5: Preventive Maintenance | C6: =WBS!D215 -> 122 | D6: =C6/6 -> 20.333333 | F6: Soumy | G6: 268 | H6: 38.285714
A7: 1.8 | B7: Epic 8: Spare Parts MRIS | C7: =WBS!D254 -> 82 | D7: =C7/6 -> 13.666667 | F7: Inderjeet | G7: 67 | H7: 9.5714286
A8: 1.9 | B8: Epic 9: Reports & Analytics | C8: =WBS!D284 -> 124 | D8: =C8/6 -> 20.666667 | F8: Grand Total | G8: 1045 | H8: 38.285714
A9: 1.10 | B9: Epic 10: Masters | C9: =WBS!D327 -> 48 | D9: =C9/6 -> 8
B10: Total | C10: =SUM(C2:C9) -> 1045 | D10: =C10/6 -> 174.16667
